Workbook
Name \I: #REF!
Name \P: #REF!
Name _1_0KOTA: #REF!
Name _1994: #REF!
Name _1995: #REF!
Name _1996: #REF!
Name _1997: #REF!
Name _1998: #REF!
Name _1999: #REF!
Name _1Q94: #REF!
Name _1Q95: #REF!
Name _2Q94: #REF!
Name _2Q95: #REF!
Name _3Q94: #REF!
Name _3Q95: #REF!
Name _4Q94: #REF!
Name _4Q95: #REF!
Name _eps94: #REF!
Name aa: #REF!
Name Actual_Price: #REF!
Name adafasd: #REF!
Name adfa: #REF!
Name adfqef: #REF!
Name AdjustedPrice: #REF!
Name adq: #REF!
Name akdeniz: #REF!
Name Analyst: #REF!
Name Analyst_Email: #REF!
Name Analyst_Phone: #REF!
Name Argentina: #REF!
Name as: #REF!
Name As_of: #REF!
Name asd: #REF!
Name asdf: #REF!
Name Astelit: #REF!
Name Atlanta_Gas_Light_Company_and_Subsidiaries: #REF!
Name BAL_SHEET: #REF!
Name BPP_CY: #REF!
Name BPP_GY: #REF!
Name BS_PL: #REF!
Name CAP: #REF!
Name cap.investment: #REF!
Name Capex: #REF!
Name Capex_96: #REF!
Name CASH: #REF!
Name CASH_FLOW: #REF!
Name ceps_00: #REF!
Name ceps_01: #REF!
Name CF: [0]!CF
Name CF_STATEMENT: #REF!
Name CFPS_Curr_Yr: #REF!
Name CFPS_Lst_Yr: #REF!
Name CFPS_Next_Yr: #REF!
Name Charts1: #REF!
Name Charts2: #REF!
Name Chile1: #REF!
Name Chile2: #REF!
Name Closed_End: #REF!
Name co_name: #REF!
Name COGS_00: #REF!

Sheet ENERJİ SEKTÖRÜ
A1: KOD | B1: ŞİRKET | C1: Piyasa Değeri (Milyon TL) | D1: Net Borç (Milyon TL) | E1: Firma Değeri (Milyon TL) | F1: Kurulu Güç (MW) | G1: Firma Değeri/ Kurulu Güç (Milyon TL/MW) | H1: FD/Kurulu Güç (USD/MW) | I1: FAVÖK (Milyon TL) | J1: FD/ FAVÖK (X) | K1: FAVÖK (Milyon USD) | L1: FAVÖK/Kurulu Güç (Milyon USD/MW) | M1: GES | N1: RES | O1: HES | P1: BES | Q1: JES | R1: Doğalgaz | S1: Termik + Linyit | T1: Toplam Kurulu Güç | U1: EPİAŞ SİSTEMİNE KAYITLI SANTRALLERİN YEKDEM/TOPLAM ORANI | V1: GES | W1: RES | X1: HES | Y1: BES | Z1: JES | AA1: Doğalgaz | AB1: Termik + Linyit | AC1: 2025 YATIRIM | AD1: 2026 YATIRIM | AE1: 2027 YATIRIM | AF1: 2030 YATIRIM | AG1: TOPLAM HEDEFLENEN YATIRIM | AH1: KAPASİTE ARTTIRIM HEDEFİ
A2: A1YEN:IS | B2: A1 Yenilenebilir Enerji | C2: =_xll.RasDaily(A2,TODAY(),"mcap",,,1000000) -> #NAME? | D2: =-_xll.RasRatio(A2,,$B$31,"Net Nakit",,,,,"C",,1000000) -> 298.89368 | E2: =C2+D2 -> #NAME? | F2: 53.4 | G2: =E2/F2 -> #NAME? | H2: =E2/(F2*$B$35) -> #NAME? | I2: =SUM(B38:E38) -> 300.06797 | J2: =E2/I2 -> #NAME? | K2: =I2/$B$35 -> #NAME? | L2: =K2/F2 -> #NAME? | M2: 53.4 | T2: =SUM(M2:S2) -> 53.4 | U2: - | V2: =M2/T2 -> 1 | W2: =N2/T2 -> 0 | X2: =O2/T2 -> 0 | Y2: =P2/T2 -> 0 | Z2: =Q2/T2 -> 0 | AA2: =R2/T2 -> 0 | AB2: =S2/T2 -> 0 | AC2: - | AD2: - | AE2: - | AF2: 7,76 Hibrit RES | AG2: 7.76 | AH2: =AG2/T2 -> 0.14531835
A3: AKENR:IS | B3: Ak Enerji | C3: =_xll.RasDaily(A3,TODAY(),"mcap",,,1000000) -> #NAME? | D3: =-_xll.RasRatio(A3,,$B$31,"Net Nakit",,,,,"C",,1000000) -> 23382.217 | E3: =C3+D3 -> #NAME? | F3: 1224 | G3: =E3/F3 -> #NAME? | H3: =E3/(F3*$B$35) -> #NAME? | I3: =SUM(B39:E39) -> 879.88132 | J3: =E3/I3 -> #NAME? | K3: =I3/$B$35 -> #NAME? | L3: =K3/F3 -> #NAME? | N3: 28 | O3: 292 | R3: 904 | T3: =SUM(M3:S3) -> 1224 | U3: 8/9 | V3: =M3/T3 -> 0 | W3: =N3/T3 -> 0.022875817 | X3: =O3/T3 -> 0.23856209 | Y3: =P3/T3 -> 0 | Z3: =Q3/T3 -> 0 | AA3: =R3/T3 -> 0.73856209 | AB3: =S3/T3 -> 0 | AC3: 8,1 MW Biyokütle Hibrit GES | AD3: 7,70 MW DGKÇS Hibrit GES | AE3: - | AF3: - | AG3: 15.8 | AH3: =AG3/T3 -> 0.012908497
A4: AKFYE:IS | B4: Akfen Yenilenebilir Enerji | C4: =_xll.RasDaily(A4,TODAY(),"mcap",,,1000000) -> #NAME? | D4: =-_xll.RasRatio(A4,,$B$31,"Net Nakit",,,,,"C",,1000000) -> 11366.832 | E4: =C4+D4 -> #NAME? | F4: 886.54 | G4: =E4/F4 -> #NAME? | H4: =E4/(F4*$B$35) -> #NAME? | I4: =SUM(B40:E40) -> 3206.0644 | J4: =E4/I4 -> #NAME? | K4: =I4/$B$35 -> #NAME? | L4: =K4/F4 -> #NAME? | M4: 121.4 | N4: 536.4 | O4: 228.75 | T4: =O4+N4+M4 -> 886.55 | U4: 15/26 | V4: =M4/T4 -> 0.13693531 | W4: =N4/T4 -> 0.60504202 | X4: =O4/T4 -> 0.25802267 | Y4: =P4/T4 -> 0 | Z4: =Q4/T4 -> 0 | AA4: =R4/T4 -> 0 | AB4: =S4/T4 -> 0 | AC4: - | AD4: - | AE4: 95 MW GES + 215 MW RES | AF4: - | AG4: 310 | AH4: =AG4/T4 -> 0.34967007
A5: AKSEN:IS | B5: Aksa Enerji | C5: =_xll.RasDaily(A5,TODAY(),"mcap",,,1000000) -> #NAME? | D5: =-_xll.RasRatio(A5,,$B$31,"Net Nakit",,,,,"C",,1000000) -> 52919.524 | E5: =C5+D5 -> #NAME? | F5: 3188 | G5: =E5/F5 -> #NAME? | H5: =E5/(F5*$B$35) -> #NAME? | I5: =SUM(B41:E41) -> 11884.674 | J5: =E5/I5 -> #NAME? | K5: =I5/$B$35 -> #NAME? | L5: =K5/F5 -> #NAME? | R5: 2170 | S5: =618+270 -> 888 | T5: =SUM(M5:S5) -> 3058 | U5: 1/2 | V5: =M5/T5 -> 0 | W5: =N5/T5 -> 0 | X5: =O5/T5 -> 0 | Y5: =P5/T5 -> 0 | Z5: =Q5/T5 -> 0 | AA5: =R5/T5 -> 0.70961413 | AB5: =S5/T5 -> 0.29038587 | AC5: - | AD5: HFO 119 MW + DGKÇS 130 MW + 25 MW RES + 100 MW GES | AE5: 100,08 MW RES + 90,5MW GES | AF5: TR DE 1000 MW KURULU GÜÇ HEDEFİ | AG5: 564.5 | AH5: =AG5/T5 -> 0.18459778
A6: AKSUE:IS | B6: Aksu Enerji | C6: =_xll.RasDaily(A6,TODAY(),"mcap",,,1000000) -> #NAME? | D6: =-_xll.RasRatio(A6,,$B$31,"Net Nakit",,,,,"C",,1000000) -> 0.275846 | E6: =C6+D6 -> #NAME? | F6: 20.11 | G6: =E6/F6 -> #NAME? | H6: =E6/(F6*$B$35) -> #NAME? | I6: =SUM(B42:E42) -> 19.118153 | J6: =E6/I6 -> #NAME? | K6: =I6/$B$35 -> #NAME? | L6: =K6/F6 -> #NAME? | M6: 7.51 | O6: =26.54+13.6 -> 40.14 | T6: =SUM(M6:S6) -> 47.65 | U6: 4/6 | V6: =M6/T6 -> 0.15760756 | W6: =N6/T6 -> 0 | X6: =O6/T6 -> 0.84239244 | Y6: =P6/T6 -> 0 | Z6: =Q6/T6 -> 0 | AA6: =R6/T6 -> 0 | AB6: =S6/T6 -> 0 | AC6: - | AD6: - | AE6: - | AF6: - | AG6: 0 | AH6: =AG6/T6 -> 0
A7: ALFAS:IS | B7: Alfa Solar Enerji | C7: =_xll.RasDaily(A7,TODAY(),"mcap",,,1000000) -> #NAME? | D7: =-_xll.RasRatio(A7,,$B$31,"Net Nakit",,,,,"C",,1000000) -> 2051.0801 | E7: =C7+D7 -> #NAME? | F7: 39.88 | G7: =E7/F7 -> #NAME? | H7: =E7/(F7*$B$35) -> #NAME? | I7: =SUM(#REF!) -> #REF! | J7: =E7/I7 -> #NAME? | K7: =I7/$B$35 -> #REF! | L7: =K7/F7 -> #REF! | M7: =39.88 -> 39.88 | T7: =SUM(M7:S7) -> 39.88 | V7: =M7/T7 -> 1 | W7: =N7/T7 -> 0 | X7: =O7/T7 -> 0 | Y7: =P7/T7 -> 0 | Z7: =Q7/T7 -> 0 | AA7: =R7/T7 -> 0 | AB7: =S7/T7 -> 0 | AC7: - | AD7: 19,39 MW GES | AF7: 1000 MW KURULU GÜÇHEDEFİ | AG7: 19.39 | AH7: =AG7/T7 -> 0.48620863
A8: AYDEM:IS | B8: Aydem Yenilenebilir Enerji | C8: =_xll.RasDaily(A8,TODAY(),"mcap",,,1000000) -> #NAME? | D8: =-_xll.RasRatio(A8,,$B$31,"Net Nakit",,,,,"C",,1000000) -> 22053.575 | E8: =C8+D8 -> #NAME? | F8: 1197.63 | G8: =E8/F8 -> #NAME? | H8: =E8/(F8*$B$35) -> #NAME? | I8: =SUM(B43:E43) -> 4830.9991 | J8: =E8/I8 -> #NAME? | K8: =I8/$B$35 -> #NAME? | L8: =K8/F8 -> #NAME? | N8: 338.65 | O8: 852.13 | Q8: 6.85 | T8: =SUM(M8:S8) -> 1197.63 | U8: 3/18 | V8: =M8/T8 -> 0 | W8: =N8/T8 -> 0.2827668 | X8: =O8/T8 -> 0.71151357 | Y8: =P8/T8 -> 0 | Z8: =Q8/T8 -> 0.0057196296 | AA8: =R8/T8 -> 0 | AB8: =S8/T8 -> 0 | AC8: - | AD8: 34 MW Depolamalı RES | AE8: 112 MW RES + 600 MW Depolamalı GES | AF8: - | AG8: 746 | AH8: =AG8/T8 -> 0.62289689
A9: AYEN:IS | B9: Ayen Enerji | C9: =_xll.RasDaily(A9,TODAY(),"mcap",,,1000000) -> #NAME? | D9: =-_xll.RasRatio(A9,,$B$31,"Net Nakit",,,,,"C",,1000000) -> 6412.994 | E9: =C9+D9 -> #NAME? | F9: 312.42 | G9: =E9/F9 -> #NAME? | H9: =E9/(F9*$B$35) -> #NAME? | I9: =SUM(B44:E44) -> 2192.187 | J9: =E9/I9 -> #NAME? | K9: =I9/$B$35 -> #NAME? | L9: =K9/F9 -> #NAME? | N9: 133.85 | O9: 68.86 | T9: =SUM(M9:S9) -> 202.71 | U9: 2/6 | V9: =M9/T9 -> 0 | W9: =N9/T9 -> 0.6603029 | X9: =O9/T9 -> 0.3396971 | Y9: =P9/T9 -> 0 | Z9: =Q9/T9 -> 0 | AA9: =R9/T9 -> 0 | AB9: =S9/T9 -> 0 | AC9: - | AD9: - | AE9: - | AF9: 12 MW RES + 111 MW HES | AG9: 123 | AH9: =AG9/T9 -> 0.60677816
A10: BIGEN:IS | B10: Birleşim Grup Enerji | C10: =_xll.RasDaily(A10,TODAY(),"mcap",,,1000000) -> #NAME? | D10: =-_xll.RasRatio(A10,,$B$31,"Net Nakit",,,,,"C",,1000000) -> 3184.6634 | E10: =C10+D10 -> #NAME? | F10: 146.18 | G10: =E10/F10 -> #NAME? | H10: =E10/(F10*$B$35) -> #NAME? | I10: =SUM(B45:E45) -> 689.20386 | J10: =E10/I10 -> #NAME? | K10: =I10/$B$35 -> #NAME? | L10: =K10/F10 -> #NAME? | M10: 178.28 | T10: =SUM(M10:S10) -> 178.28 | U10: 13/14 | V10: =M10/T10 -> 1 | W10: =N10/T10 -> 0 | X10: =O10/T10 -> 0 | Y10: =P10/T10 -> 0 | Z10: =Q10/T10 -> 0 | AA10: =R10/T10 -> 0 | AB10: =S10/T10 -> 0 | AC10: - | AD10: - | AE10: - | AF10: 24 MW RES | AG10: 24 | AH10: =AG10/T10 -> 0.1346197
A11: BIOEN:IS | B11: Biotrend Çevre ve Enerji | C11: =_xll.RasDaily(A11,TODAY(),"mcap",,,1000000) -> #NAME? | D11: =-_xll.RasRatio(A11,,$B$31,"Net Nakit",,,,,"C",,1000000) -> 5733.8572 | E11: =C11+D11 -> #NAME? | F11: 114.2 | G11: =E11/F11 -> #NAME? | H11: =E11/(F11*$B$35) -> #NAME? | I11: =SUM(B46:E46) -> 248.52688 | J11: =E11/I11 -> #NAME? | K11: =I11/$B$35 -> #NAME? | L11: =K11/F11 -> #NAME? | P11: 116.94 | T11: =SUM(M11:S11) -> 116.94 | U11: 12/14 | V11: =M11/T11 -> 0 | W11: =N11/T11 -> 0 | X11: =O11/T11 -> 0 | Y11: =P11/T11 -> 1 | Z11: =Q11/T11 -> 0 | AA11: =R11/T11 -> 0 | AB11: =S11/T11 -> 0 | AC11: - | AD11: - | AE11: 30 MW BES | AF11: 24 MW BES | AG11: 54 | AH11: =AG11/T11 -> 0.46177527
A12: CANTE:IS | B12: Çan2 Termik Santrali | C12: =_xll.RasDaily(A12,TODAY(),"mcap",,,1000000) -> #NAME? | D12: =-_xll.RasRatio(A12,,$B$31,"Net Nakit",,,,,"C",,1000000) -> -1468.7565 | E12: =C12+D12 -> #NAME? | F12: 330 | G12: =E12/F12 -> #NAME? | H12: =E12/(F12*$B$35) -> #NAME? | I12: =SUM(B47:E47) -> 2111.4752 | J12: =E12/I12 -> #NAME? | K12: =I12/$B$35 -> #NAME? | L12: =K12/F12 -> #NAME? | S12: 330 | T12: =SUM(M12:S12) -> 330 | U12: 0/1 | V12: =M12/T12 -> 0 | W12: =N12/T12 -> 0 | X12: =O12/T12 -> 0 | Y12: =P12/T12 -> 0 | Z12: =Q12/T12 -> 0 | AA12: =R12/T12 -> 0 | AB12: =S12/T12 -> 1 | AC12: - | AD12: - | AE12: - | AF12: - | AG12: 0 | AH12: =AG12/T12 -> 0
A13: CATES:IS | B13: Çatalağzı Termik Santrali | C13: =_xll.RasDaily(A13,TODAY(),"mcap",,,1000000) -> #NAME? | D13: =-_xll.RasRatio(A13,,$B$31,"Net Nakit",,,,,"C",,1000000) -> -896.75339 | E13: =C13+D13 -> #NAME? | F13: 314.68 | G13: =E13/F13 -> #NAME? | H13: =E13/(F13*$B$35) -> #NAME? | I13: =SUM(B48:E48) -> 385.89506 | J13: =E13/I13 -> #NAME? | K13: =I13/$B$35 -> #NAME? | L13: =K13/F13 -> #NAME? | S13: 314.68 | T13: =SUM(M13:S13) -> 314.68 | U13: 0/1 | V13: =M13/T13 -> 0 | W13: =N13/T13 -> 0 | X13: =O13/T13 -> 0 | Y13: =P13/T13 -> 0 | Z13: =Q13/T13 -> 0 | AA13: =R13/T13 -> 0 | AB13: =S13/T13 -> 1 | AC13: - | AD13: - | AE13: - | AF13: - | AG13: 0 | AH13: =AG13/T13 -> 0
A14: CONSE:IS | B14: Consus Enerji | C14: =_xll.RasDaily(A14,TODAY(),"mcap",,,1000000) -> #NAME? | D14: =-_xll.RasRatio(A14,,$B$31,"Net Nakit",,,,,"C",,1000000) -> 3913.3189 | E14: =C14+D14 -> #NAME? | F14: 110.5 | G14: =E14/F14 -> #NAME? | H14: =E14/(F14*$B$35) -> #NAME? | I14: =SUM(B49:E49) -> 350.088 | J14: =E14/I14 -> #NAME? | K14: =I14/$B$35 -> #NAME? | L14: =K14/F14 -> #NAME? | M14: 10.8 | P14: 34.2 | T14: 107.4 | U14: 3/3 | V14: =M14/T14 -> 0.10055866 | W14: =N14/T14 -> 0 | X14: =O14/T14 -> 0 | Y14: =P14/T14 -> 0.31843575 | Z14: =Q14/T14 -> 0 | AA14: =R14/T14 -> 0 | AB14: =S14/T14 -> 0 | AC14: - | AD14: - | AE14: 25 MW GES + 50 MW DGKÇS | AF14: - | AG14: 75 | AH14: =AG14/T14 -> 0.69832402
A15: CWENE:IS | B15: CW Enerji | C15: =_xll.RasDaily(A15,TODAY(),"mcap",,,1000000) -> #NAME? | D15: =-_xll.RasRatio(A15,,$B$31,"Net Nakit",,,,,"C",,1000000) -> 8070.0855 | E15: =C15+D15 -> #NAME? | F15: 14.36 | G15: =E15/F15 -> #NAME? | H15: =E15/(F15*$B$35) -> #NAME? | I15: =SUM(#REF!) -> #REF! | J15: =E15/I15 -> #NAME? | K15: =I15/$B$35 -> #REF! | L15: =K15/F15 -> #REF! | M15: 14.36 | T15: =SUM(M15:S15) -> 14.36 | V15: =M15/T15 -> 1 | W15: =N15/T15 -> 0 | X15: =O15/T15 -> 0 | Y15: =P15/T15 -> 0 | Z15: =Q15/T15 -> 0 | AA15: =R15/T15 -> 0 | AB15: =S15/T15 -> 0 | AC15: - | AD15: - | AE15: - | AF15: - | AG15: 0 | AH15: =AG15/T15 -> 0
A16: ECOGR:IS | B16: EcoGreen Enerji | C16: =_xll.RasDaily(A16,TODAY(),"mcap",,,1000000) -> #NAME? | D16: =-_xll.RasRatio(A16,,$B$31,"Net Nakit",,,,,"C",,1000000) -> 8256.1982 | E16: =C16+D16 -> #NAME? | F16: 179.34 | G16: =E16/F16 -> #NAME? | H16: =E16/(F16*$B$35) -> #NAME? | I16: =SUM(B50:E50) -> 1910.5224 | J16: =E16/I16 -> #NAME? | K16: =I16/$B$35 -> #NAME? | L16: =K16/F16 -> #NAME? | M16: 156.94 | P16: 22.4 | T16: =SUM(M16:S16) -> 179.34 | U16: 1/11 | V16: =M16/T16 -> 0.87509758 | W16: =N16/T16 -> 0 | X16: =O16/T16 -> 0 | Y16: =P16/T16 -> 0.12490242 | Z16: =Q16/T16 -> 0 | AA16: =R16/T16 -> 0 | AB16: =S16/T16 -> 0 | AC16: - | AD16: 50 MW GES | AE16: - | AF16: 100 MW RES + 100 MW Depolamalı RES | AG16: 250 | AH16: =AG16/T16 -> 1.3940002
A17: ENDAE:IS | B17: Enda Enerji | C17: =_xll.RasDaily(A17,TODAY(),"mcap",,,1000000) -> #NAME? | D17: =-_xll.RasRatio(A17,,$B$31,"Net Nakit",,,,,"C",,1000000) -> -1478.3514 | E17: =C17+D17 -> #NAME? | F17: 189.12 | G17: =E17/F17 -> #NAME? | H17: =E17/(F17*$B$35) -> #NAME? | I17: =SUM(B51:E51) -> 573.27126 | J17: =E17/I17 -> #NAME? | K17: =I17/$B$35 -> #NAME? | L17: =K17/F17 -> #NAME? | M17: 6.66 | N17: 47.83 | O17: 83.55 | Q17: 5.59 | T17: =SUM(M17:S17) -> 143.63 | U17: 8/13 | V17: =M17/T17 -> 0.046369143 | W17: =N17/T17 -> 0.33300842 | X17: =O17/T17 -> 0.58170299 | Y17: =P17/T17 -> 0 | Z17: =Q17/T17 -> 0.038919446 | AA17: =R17/T17 -> 0 | AB17: =S17/T17 -> 0 | AC17: - | AD17: - | AE17: - | AF17: 17,95 MW RES + 2,2 MW HES + 54 MW GES | AG17: 74.15 | AH17: =AG17/T17 -> 0.51625705
A18: ENTRA:IS | B18: IC Enterra Yenilenebilir Enerji | C18: =_xll.RasDaily(A18,TODAY(),"mcap",,,1000000) -> #NAME? | D18: =-_xll.RasRatio(A18,,$B$31,"Net Nakit",,,,,"C",,1000000) -> 11618.956 | E18: =C18+D18 -> #NAME? | F18: 487.982 | G18: =E18/F18 -> #NAME? | H18: =E18/(F18*$B$35) -> #NAME? | I18: =SUM(B52:E52) -> 2905.8691 | J18: =E18/I18 -> #NAME? | K18: =I18/$B$35 -> #NAME? | L18: =K18/F18 -> #NAME? | M18: 100 | O18: 387.982 | T18: =SUM(M18:S18) -> 487.982 | U18: 2/10 | V18: =M18/T18 -> 0.20492559 | W18: =N18/T18 -> 0 | X18: =O18/T18 -> 0.79507441 | Y18: =P18/T18 -> 0 | Z18: =Q18/T18 -> 0 | AA18: =R18/T18 -> 0 | AB18: =S18/T18 -> 0 | AC18: - | AD18: - | AE18: - | AF18: 135 MW RES | AG18: 45 | AH18: =AG18/T18 -> 0.092216516
A19: GWIND:IS | B19: Galata Wind Enerji | C19: =_xll.RasDaily(A19,TODAY(),"mcap",,,1000000) -> #NAME? | D19: =-_xll.RasRatio(A19,,$B$31,"Net Nakit",,,,,"C",,1000000) -> 1593.2409 | E19: =C19+D19 -> #NAME? | F19: 354.2 | G19: =E19/F19 -> #NAME? | H19: =E19/(F19*$B$35) -> #NAME? | I19: =SUM(B53:E53) -> 1918.4335 | J19: =E19/I19 -> #NAME? | K19: =I19/$B$35 -> #NAME? | L19: =K19/F19 -> #NAME? | M19: =34.1+36.2 -> 70.3 | N19: 283.9 | T19: =SUM(M19:S19) -> 354.2 | U19: 4/6 | V19: =M19/T19 -> 0.19847544 | W19: =N19/T19 -> 0.80152456 | X19: =O19/T19 -> 0 | Y19: =P19/T19 -> 0 | Z19: =Q19/T19 -> 0 | AA19: =R19/T19 -> 0 | AB19: =S19/T19 -> 0 | AC19: - | AD19: 27,2 MW RES | AE19: 300 MW RES + 110 MW GES | AF19: 1000 MW KURULU GÜÇ HEDEFİ | AG19: 437.2 | AH19: =AG19/T19 -> 1.2343309
A20: HUNER:IS | B20: Hun Yenilenebilir Enerji | C20: =_xll.RasDaily(A20,TODAY(),"mcap",,,1000000) -> #NAME? | D20: =-_xll.RasRatio(A20,,$B$31,"Net Nakit",,,,,"C",,1000000) -> 1918.034 | E20: =C20+D20 -> #NAME? | F20: 103.1 | G20: =E20/F20 -> #NAME? | H20: =E20/(F20*$B$35) -> #NAME? | I20: =SUM(#REF!) -> #REF! | J20: =E20/I20 -> #NAME? | K20: =I20/$B$35 -> #REF! | L20: =K20/F20 -> #REF! | M20: 66.5 | O20: 26.1 | P20: 10.5 | T20: =SUM(M20:S20) -> 103.1 | V20: =M20/T20 -> 0.64500485 | W20: =N20/T20 -> 0 | X20: =O20/T20 -> 0.25315228 | Y20: =P20/T20 -> 0.10184287 | Z20: =Q20/T20 -> 0 | AA20: =R20/T20 -> 0 | AB20: =S20/T20 -> 0 | AC20: - | AD20: - | AE20: - | AF20: 5,08 MW GES | AG20: 5.08 | AH20: =AG20/T20 -> 0.049272551
A21: IZENR:IS | B21: İzdemir Enerji | C21: =_xll.RasDaily(A21,TODAY(),"mcap",,,1000000) -> #NAME? | D21: =-_xll.RasRatio(A21,,$B$31,"Net Nakit",,,,,"C",,1000000) -> 325.04677 | E21: =C21+D21 -> #NAME? | F21: 513.18 | G21: =E21/F21 -> #NAME? | H21: =E21/(F21*$B$35) -> #NAME? | I21: =SUM(B54:E54) -> 1735.4664 | J21: =E21/I21 -> #NAME? | K21: =I21/$B$35 -> #NAME? | L21: =K21/F21 -> #NAME? | M21: 143.18 | S21: 370 | T21: =SUM(M21:S21) -> 513.18 | U21: 0/4 | V21: =M21/T21 -> 0.27900542 | W21: =N21/T21 -> 0 | X21: =O21/T21 -> 0 | Y21: =P21/T21 -> 0 | Z21: =Q21/T21 -> 0 | AA21: =R21/T21 -> 0 | AB21: =S21/T21 -> 0.72099458 | AC21: - | AD21: - | AE21: - | AF21: - | AG21: 0 | AH21: =AG21/T21 -> 0
A22: LYDYE:IS | B22: Lydia Yenilebilir Enerji | C22: =_xll.RasDaily(A22,TODAY(),"mcap",,,1000000) -> #NAME? | D22: =-_xll.RasRatio(A22,,$B$31,"Net Nakit",,,,,"C",,1000000) -> -25.327874 | E22: =C22+D22 -> #NAME? | F22: 6.29 | G22: =E22/F22 -> #NAME? | H22: =E22/(F22*$B$35) -> #NAME? | I22: =SUM(B55:E55) -> 17.154661 | J22: =E22/I22 -> #NAME? | K22: =I22/$B$35 -> #NAME? | L22: =K22/F22 -> #NAME? | M22: 6.29 | T22: =SUM(M22:S22) -> 6.29 | U22: 0/5 | V22: =M22/T22 -> 1 | W22: =N22/T22 -> 0 | X22: =O22/T22 -> 0 | Y22: =P22/T22 -> 0 | Z22: =Q22/T22 -> 0 | AA22: =R22/T22 -> 0 | AB22: =S22/T22 -> 0 | AC22: - | AD22: - | AE22: - | AF22: - | AG22: 0 | AH22: =AG22/T22 -> 0
A23: MOGAN:IS | B23: Mogan Enerji | C23: =_xll.RasDaily(A23,TODAY(),"mcap",,,1000000) -> #NAME? | D23: =-_xll.RasRatio(A23,,$B$31,"Net Nakit",,,,,"C",,1000000) -> 30095.211 | E23: =C23+D23 -> #NAME? | F23: 972.77 | G23: =E23/F23 -> #NAME? | H23: =E23/(F23*$B$35) -> #NAME? | I23: =SUM(B56:E56) -> 7058.6308 | J23: =E23/I23 -> #NAME? | K23: =I23/$B$35 -> #NAME? | L23: =K23/F23 -> #NAME? | N23: 489.24 | O23: 63.59 | Q23: 233.91 | T23: =SUM(M23:S23) -> 786.74 | U23: 8/18 | V23: =M23/T23 -> 0 | W23: =N23/T23 -> 0.62185728 | X23: =O23/T23 -> 0.080827211 | Y23: =P23/T23 -> 0 | Z23: =Q23/T23 -> 0.2973155 | AA23: =R23/T23 -> 0 | AB23: =S23/T23 -> 0 | AF23: 74,88 MW RES | AG23: 74.88 | AH23: =AG23/T23 -> 0.095177568
A24: ODAS:IS | B24: Odaş Elektrik | C24: =_xll.RasDaily(A24,TODAY(),"mcap",,,1000000) -> #NAME? | D24: =-_xll.RasRatio(A24,,$B$31,"Net Nakit",,,,,"C",,1000000) -> -1540.4054 | E24: =C24+D24 -> #NAME? | F24: 270.6 | G24: =E24/F24 -> #NAME? | H24: =E24/(F24*$B$35) -> #NAME? | I24: =SUM(#REF!) -> #REF! | J24: =E24/I24 -> #NAME? | K24: =I24/$B$35 -> #REF! | L24: =K24/F24 -> #REF! | R24: 174 | S24: 96.6 | T24: =SUM(M24:S24) -> 270.6 | V24: =M24/T24 -> 0 | W24: =N24/T24 -> 0 | X24: =O24/T24 -> 0 | Y24: =P24/T24 -> 0 | Z24: =Q24/T24 -> 0 | AA24: =R24/T24 -> 0.64301552 | AB24: =S24/T24 -> 0.35698448 | AC24: - | AD24: - | AE24: - | AF24: - | AG24: 0 | AH24: =AG24/T24 -> 0
A25: PAMEL:IS | B25: Pamel Yenilenebilir Elektrik Üretimi | C25: =_xll.RasDaily(A25,TODAY(),"mcap",,,1000000) -> #NAME? | D25: =-_xll.RasRatio(A25,,$B$31,"Net Nakit",,,,,"C",,1000000) -> -4.121764 | E25: =C25+D25 -> #NAME? | F25: 18.454 | G25: =E25/F25 -> #NAME? | H25: =E25/(F25*$B$35) -> #NAME? | I25: =SUM(B57:E57) -> 9.0790455 | J25: =E25/I25 -> #NAME? | K25: =I25/$B$35 -> #NAME? | L25: =K25/F25 -> #NAME? | M25: 4.018 | O25: 14.436 | T25: =SUM(M25:S25) -> 18.454 | V25: =M25/T25 -> 0.21773057 | W25: =N25/T25 -> 0 | X25: =O25/T25 -> 0.78226943 | Y25: =P25/T25 -> 0 | Z25: =Q25/T25 -> 0 | AA25: =R25/T25 -> 0 | AB25: =S25/T25 -> 0 | AC25: - | AD25: - | AE25: - | AF25: - | AG25: 0 | AH25: =AG25/T25 -> 0
A26: SMRTG:IS | B26: Smart Güneş | C26: =_xll.RasDaily(A26,TODAY(),"mcap",,,1000000) -> #NAME? | D26: =-_xll.RasRatio(A26,,$B$31,"Net Nakit",,,,,"C",,1000000) -> 10536.162 | E26: =C26+D26 -> #NAME? | F26: 93.01 | G26: =E26/F26 -> #NAME? | H26: =E26/(F26*$B$35) -> #NAME? | I26: =SUM(#REF!) -> #REF! | J26: =E26/I26 -> #NAME? | K26: =I26/$B$35 -> #REF! | L26: =K26/F26 -> #REF! | M26: =100*0.9301 -> 93.01 | T26: =SUM(M26:S26) -> 93.01 | V26: =M26/T26 -> 1 | W26: =N26/T26 -> 0 | X26: =O26/T26 -> 0 | Y26: =P26/T26 -> 0 | Z26: =Q26/T26 -> 0 | AA26: =R26/T26 -> 0 | AB26: =S26/T26 -> 0 | AC26: - | AD26: - | AE26: - | AF26: 244,85 MW GES | AG26: 244.85 | AH26: =AG26/T26 -> 2.6325126
A27: TATEN:IS | B27: Tatlıpınar Enerji | C27: =_xll.RasDaily(A27,TODAY(),"mcap",,,1000000) -> #NAME? | D27: =-_xll.RasRatio(A27,,$B$31,"Net Nakit",,,,,"C",,1000000) -> 6973.4525 | E27: =C27+D27 -> #NAME? | F27: 362.5 | G27: =E27/F27 -> #NAME? | H27: =E27/(F27*$B$35) -> #NAME? | I27: =SUM(B58:E58) -> 1645.7176 | J27: =E27/I27 -> #NAME? | K27: =I27/$B$35 -> #NAME? | L27: =K27/F27 -> #NAME? | M27: 82.28 | N27: 258.5 | O27: 21.5 | T27: 362.5 | U27: 6/6 | V27: =M27/T27 -> 0.22697931 | W27: =N27/T27 -> 0.71310345 | X27: =O27/T27 -> 0.059310345 | Y27: =P27/T27 -> 0 | Z27: =Q27/T27 -> 0 | AA27: =R27/T27 -> 0 | AB27: =S27/T27 -> 0 | AC27: - | AD27: - | AE27: - | AF27: - | AG27: 0 | AH27: =AG27/T27 -> 0
A28: ZEDUR:IS | B28: Zedur Enerj | C28: =_xll.RasDaily(A28,TODAY(),"mcap",,,1000000) -> #NAME? | D28: =-_xll.RasRatio(A28,,$B$31,"Net Nakit",,,,,"C",,1000000) -> 463.82712 | E28: =C28+D28 -> #NAME? | F28: 15.8 | G28: =E28/F28 -> #NAME? | H28: =E28/(F28*$B$35) -> #NAME? | I28: =SUM(B59:E59) -> 21.938434 | J28: =E28/I28 -> #NAME? | K28: =I28/$B$35 -> #NAME? | L28: =K28/F28 -> #NAME? | M28: 12.2 | O28: 3.6 | T28: =SUM(M28:S28) -> 15.8 | U28: 3/4 | V28: =M28/T28 -> 0.7721519 | W28: =N28/T28 -> 0 | X28: =O28/T28 -> 0.2278481 | Y28: =P28/T28 -> 0 | Z28: =Q28/T28 -> 0 | AA28: =R28/T28 -> 0 | AB28: =S28/T28 -> 0 | AC28: - | AD28: - | AE28: - | AF28: 15 MW Depolamalı GES | AG28: 15 | AH28: =AG28/T28 -> 0.94936709
A29: ZOREN:IS | B29: Zorlu Enerji | C29: =_xll.RasDaily(A29,TODAY(),"mcap",,,1000000) -> #NAME? | D29: =-_xll.RasRatio(A29,,$B$31,"Net Nakit",,,,,"C",,1000000) -> 55179.191 | E29: =C29+D29 -> #NAME? | F29: =473.45+57.9 -> 531.35 | G29: =E29/F29 -> #NAME? | H29: =E29/(F29*$B$35) -> #NAME? | I29: =SUM(B60:E60) -> 6161.8721 | J29: =E29/I29 -> #NAME? | K29: =I29/$B$35 -> #NAME? | L29: =K29/F29 -> #NAME? | N29: 135 | O29: 118.92 | Q29: 305 | R29: 49.53 | T29: =SUM(M29:S29) -> 608.45 | U29: 2/13 | V29: =M29/T29 -> 0 | W29: =N29/T29 -> 0.22187526 | X29: =O29/T29 -> 0.19544745 | Y29: =P29/T29 -> 0 | Z29: =Q29/T29 -> 0.50127373 | AA29: =R29/T29 -> 0.081403566 | AB29: =S29/T29 -> 0 | AC29: - | AD29: - | AE29: - | AF29: 375 MW RES + 63,6 JES | AG29: 438.6 | AH29: =AG29/T29 -> 0.72084806
B31: 46112 | C31: 2025
A33: Tarih | B33: USD_DS:TFX
A34: =TODAY() -> 46246 | B34: =_xll.RasDaily(B$33,$A$34,"close",,TRUE(),1) -> #NAME?
A35: =TODAY() -> 46246 | B35: =_xll.RasDaily(B$33,$A$35,"close",,TRUE(),1) -> #NAME?
A37: FAVÖK | B37: 2026/1Q | C37: 2025/4Q | D37: 2025/3Q | E37: 2025/2Q | G37: Net Borç | H37: Net Borç/FAVÖK | I37: Özkaynaklar
A38: A1YEN:IS | B38: =_xll.RasRatio(A2,$B$37,$B$37,"EBITDA","XI_29","LOCAL",,FALSE(),"AC",,1000000) -> 37.083456 | C38: =_xll.RasRatio(A2,$C$37,$C$37,"EBITDA","XI_29","LOCAL",,FALSE(),"AC",,1000000) -> 79.314649 | D38: =_xll.RasRatio(A2,$D$37,$D$37,"EBITDA","XI_29","LOCAL",,FALSE(),"AC",,1000000) -> 103.06845 | E38: =_xll.RasRatio(A2,$E$37,$E$37,"EBITDA","XI_29","LOCAL",,FALSE(),"AC",,1000000) -> 80.60141 | G38: =-_xll.RasRatio(A38,,$B$37,"Net Nakit",,,,,"C",,1000000) -> 298.89368 | H38: =G38/SUM(B38:E38) -> 0.9960866 | I38: =_xll.RasFinancial(A38,"2026/3M",2400,"XI_29","LOCAL",,FALSE(),"AC",,1000000) -> 3375.5993
A39: AKENR:IS | B39: =_xll.RasRatio(A3,$B$37,$B$37,"EBITDA","XI_29","LOCAL",,FALSE(),"AC",,1000000) -> 604.698 | C39: =_xll.RasRatio(A3,$C$37,$C$37,"EBITDA","XI_29","LOCAL",,FALSE(),"AC",,1000000) -> 92.158321 | D39: =_xll.RasRatio(A3,$D$37,$D$37,"EBITDA","XI_29","LOCAL",,FALSE(),"AC",,1000000) -> 38.723 | E39: =_xll.RasRatio(A3,$E$37,$E$37,"EBITDA","XI_29","LOCAL",,FALSE(),"AC",,1000000) -> 144.302 | G39: =-_xll.RasRatio(A39,,$B$37,"Net Nakit",,,,,"C",,1000000) -> 23382.217 | H39: =G39/SUM(B39:E39) -> 26.574285 | I39: =_xll.RasFinancial(A39,"2026/3M",2400,"XI_29","LOCAL",,FALSE(),"AC",,1000000) -> 14552.864
A40: AKFYE:IS | B40: =_xll.RasRatio(A4,$B$37,$B$37,"EBITDA","XI_29","LOCAL",,FALSE(),"AC",,1000000) -> 870.329 | C40: =_xll.RasRatio(A4,$C$37,$C$37,"EBITDA","XI_29","LOCAL",,FALSE(),"AC",,1000000) -> 712.71341 | D40: =_xll.RasRatio(A4,$D$37,$D$37,"EBITDA","XI_29","LOCAL",,FALSE(),"AC",,1000000) -> 803.362 | E40: =_xll.RasRatio(A4,$E$37,$E$37,"EBITDA","XI_29","LOCAL",,FALSE(),"AC",,1000000) -> 819.66 | G40: =-_xll.RasRatio(A40,,$B$37,"Net Nakit",,,,,"C",,1000000) -> 11366.832 | H40: =G40/SUM(B40:E40) -> 3.545416 | I40: =_xll.RasFinancial(A40,"2026/3M",2400,"XI_29","LOCAL",,FALSE(),"AC",,1000000) -> 62456.935
A41: AKSEN:IS | B41: =_xll.RasRatio(A5,$B$37,$B$37,"EBITDA","XI_29","LOCAL",,FALSE(),"AC",,1000000) -> 3232.3651 | C41: =_xll.RasRatio(A5,$C$37,$C$37,"EBITDA","XI_29","LOCAL",,FALSE(),"AC",,1000000) -> 2928.5863 | D41: =_xll.RasRatio(A5,$D$37,$D$37,"EBITDA","XI_29","LOCAL",,FALSE(),"AC",,1000000) -> 3079.8861 | E41: =_xll.RasRatio(A5,$E$37,$E$37,"EBITDA","XI_29","LOCAL",,FALSE(),"AC",,1000000) -> 2643.8368 | G41: =-_xll.RasRatio(A41,,$B$37,"Net Nakit",,,,,"C",,1000000) -> 52919.524 | H41: =G41/SUM(B41:E41) -> 4.4527534 | I41: =_xll.RasFinancial(A41,"2026/3M",2400,"XI_29","LOCAL",,FALSE(),"AC",,1000000) -> 70028.292
A42: AKSUE:IS | B42: =_xll.RasRatio(A6,$B$37,$B$37,"EBITDA","XI_29","LOCAL",,FALSE(),"AC",,1000000) -> 0.663063 | C42: =_xll.RasRatio(A6,$C$37,$C$37,"EBITDA","XI_29","LOCAL",,FALSE(),"AC",,1000000) -> 4.8559399 | D42: =_xll.RasRatio(A6,$D$37,$D$37,"EBITDA","XI_29","LOCAL",,FALSE(),"AC",,1000000) -> 5.5338041 | E42: =_xll.RasRatio(A6,$E$37,$E$37,"EBITDA","XI_29","LOCAL",,FALSE(),"AC",,1000000) -> 8.065346 | G42: =-_xll.RasRatio(A42,,$B$37,"Net Nakit",,,,,"C",,1000000) -> 0.275846 | H42: =G42/SUM(B42:E42) -> 0.014428486 | I42: =_xll.RasFinancial(A42,"2026/3M",2400,"XI_29","LOCAL",,FALSE(),"AC",,1000000) -> 989.7261
A43: AYDEM:IS | B43: =_xll.RasRatio(A8,$B$37,$B$37,"EBITDA","XI_29","LOCAL",,FALSE(),"AC",,1000000) -> 1375.8077 | C43: =_xll.RasRatio(A8,$C$37,$C$37,"EBITDA","XI_29","LOCAL",,FALSE(),"AC",,1000000) -> 747.27239 | D43: =_xll.RasRatio(A8,$D$37,$D$37,"EBITDA","XI_29","LOCAL",,FALSE(),"AC",,1000000) -> 1285.098 | E43: =_xll.RasRatio(A8,$E$37,$E$37,"EBITDA","XI_29","LOCAL",,FALSE(),"AC",,1000000) -> 1422.821 | G43: =-_xll.RasRatio(A43,,$B$37,"Net Nakit",,,,,"C",,1000000) -> 22053.575 | H43: =G43/SUM(B43:E43) -> 4.5650134 | I43: =_xll.RasFinancial(A43,"2026/3M",2400,"XI_29","LOCAL",,FALSE(),"AC",,1000000) -> 41071.171
...

Sheet ELEKTRİK verileri
A1: Mwh üretim | B1: 1Q25 | C1: 2Q25 | D1: 3Q25 | E1: 4Q25 | F1: 1Q26 | G1: 2Q26
A2: Doğalgaz | B2: 20947165 | C2: 12220441 | D2: 23756049 | E2: 21440711 | F2: 12712375 | G2: 7337652.5
A3: Barajlı | B3: 10582363 | C3: 12191756 | D3: 10859817 | E3: 7743441.8 | F3: 16740874 | G3: 25603665
A4: Linyit | B4: 8987910.3 | C4: 8995259.3 | D4: 10452822 | E4: 10424847 | F4: 9475904.5 | G4: 8690906
A5: Akarsu | B5: 3750644.4 | C5: 7283644.8 | D5: 2543309.8 | E5: 2260629.3 | F5: 6269044.5 | G5: 8208168.5
A6: İthal Kömür | B6: 19641395 | C6: 14251331 | D6: 21191763 | E6: 21028349 | F6: 17066861 | G6: 6700763.4
A7: Rüzgar | B7: 9314261.5 | C7: 9380815.4 | D7: 11884244 | E7: 8666695.3 | F7: 12870144 | G7: 8401529.1
A8: Güneş | B8: 1294755.7 | C8: 2307056.6 | D8: 2682436.9 | E8: 1448491.8 | F8: 1349259.5 | G8: 2249673.4
A9: Fuel Oil | B9: 184117.19 | C9: 192025.53 | D9: 194897.9 | E9: 185759.2 | F9: 182468.41 | G9: 178303.4
A10: Jeotermal | B10: 2887915.8 | C10: 2572268.9 | D10: 2336947 | E10: 2850593.1 | F10: 2842539.6 | G10: 2584530.2
A11: Asfaltit Kömür | B11: 423939.03 | C11: 333361.71 | D11: 576334.16 | E11: 556916.17 | F11: 452054.26 | G11: 427675.46
A12: Taş Kömür | B12: 1104431.1 | C12: 1097623.7 | D12: 1197458.3 | E12: 1141455.4 | F12: 991856.29 | G12: 1017904.3
A13: Biyokütle | B13: 2126655.6 | C13: 2066677.9 | D13: 2048066.6 | E13: 2161695 | F13: 2020109.1 | G13: 1920635.2
... A18: Toplam | B18: 80288430 | C18: 73240681 | D18: 89349551 | E18: 79600419 | F18: 82335949 | G18: 72864456
A20: tüketim mwh | B20: 1Q25 | C20: 2Q25 | D20: 3Q25 | E20: 4Q25 | F20: 1Q26 | G20: 2Q26
B21: 85,439,509.18 | C21: 82,538,168.01 | D21: 99,322,757.51 | E21: 83,355,495.20 | F21: 80,505,466.25 | G21: 83,244,799.25

Sheet SONUÇ
C1: 2305
A2: CANTE | C2: Çan2 Termik Santrali (MWh) | E2: Faaliyet Rapor Üretim Verisi (MWh) | F2: Yıllık Bazda Sapma Oranı | G2: PTF Ağırlıklı Ort (MWh/TL) | H2: Aylık Ort Dolar Kuru | I2: PTF Ağırlıklı Ort (MWh/USD) | J2: PTF Ağırlıklı Ort Ciro Tahmin(Milyon TL) | L2: Ciro (Milyon TL) | M2: Ciro Sapma | N2: Ciro EM Hariç (Milyon TL) | O2: Ciro EM Hariç Sapma | P2: Ortalama Ciro Sapma Oranı | Q2: Ortalama EM Hariç Ciro Sapma Oranı | R2: Ciro Tahmini (Milyon TL) | S2: EM Hariç Ciro Tahmini (Milyon TL) | T2: COGS (Milyon TL) | U2: EM Hariç COGS (Milyon TL) | V2: Average COGS per Unit | W2: Gross Profit (Milyon TL)
A3: 2025/1Q | B3: 45658 | C3: 162833 | G3: 2537.99 | H3: 35.48 | I3: =G3/H3 -> 71.532976 | J3: =C3*G3/1000000 -> 413.26853
B4: 45689 | C4: 67265 | G4: 2506.77 | H4: 36.12 | I4: =G4/H4 -> 69.401163 | J4: =C4*G4/1000000 -> 168.61788
B5: 45717 | C5: 68555 | D5: =SUM(C3:C5) -> 298653 | G5: 2207.18 | H5: 37.04 | I5: =G5/H5 -> 59.589093 | J5: =C5*G5/1000000 -> 151.31322 | K5: =SUM(J3:J5) -> 733.19963 | L5: =_xll.RasFinancial($A$2,A3,3120,"XI_29","LOCAL",,FALSE(),"AC",,1000000) -> 1277.8219 | M5: =(K5/L5)-1 -> -0.42621141 | N5: =_xll.RasFinancial($A$2,"2025/3M",3120,"XI_29","LOCAL",,FALSE(),"ACO",,1000000) -> 976.42138 | O5: =(K5/N5)-1 -> -0.24909506 | T5: =-_xll.RasFinancial($A$2,A3,999010002,"IND_INT_DTL","LOCAL",,FALSE(),"AC",,1000000) -> 1219.6552 | U5: =-_xll.RasFinancial($A$2,"2025/3M",999010002,"IND_INT_DTL","LOCAL",,FALSE(),"ACO",,1000000) -> 931.97452 | V5: =T5/N5 -> 1.2491075 | W5: =L5-T5 -> 58.166667
A6: 2025/2Q | B6: 45748 | C6: 147924 | G6: 2489.25 | H6: 38.05 | I6: =G6/H6 -> 65.420499 | J6: =C6*G6/1000000 -> 368.21982
B7: 45778 | C7: 197461 | G7: 2474.98 | H7: 38.72 | I7: =G7/H7 -> 63.919938 | J7: =C7*G7/1000000 -> 488.71203
B8: 45809 | C8: 151960 | D8: =SUM(C6:C8) -> 497345 | G8: 2240.61 | H8: 39.37 | I8: =G8/H8 -> 56.911608 | J8: =C8*G8/1000000 -> 340.4831 | K8: =SUM(J6:J8) -> 1197.4149 | L8: =_xll.RasFinancial($A$2,A6,3120,"XI_29","LOCAL",,FALSE(),"AC",,1000000) -> 1516.4794 | M8: =(K8/L8)-1 -> -0.21039816 | N8: =(_xll.RasFinancial($A$2,"2025/6M",3120,"XI_29","LOCAL",,FALSE(),"ACO",,1000000))-N5 -> 1575.1303 | O8: =(K8/N8)-1 -> -0.23979945 | T8: =-_xll.RasFinancial($A$2,A6,999010002,"IND_INT_DTL","LOCAL",,FALSE(),"AC",,1000000) -> 1404.8627 | U8: =(-_xll.RasFinancial($A$2,"2025/6M",999010002,"IND_INT_DTL","LOCAL",,FALSE(),"ACO",,1000000)-U5) -> 1460.8438 | V8: =T8/N8 -> 0.8919025 | W8: =L8-T8 -> 111.61674
A9: 2025/3Q | B9: 45839 | C9: 169962 | G9: 2981.73 | H9: 40.14 | I9: =G9/H9 -> 74.283259 | J9: =C9*G9/1000000 -> 506.78079
B10: 45870 | C10: 197461 | G10: 2952.26 | H10: 40.75 | I10: =G10/H10 -> 72.448098 | J10: =C10*G10/1000000 -> 582.95621
B11: 45901 | C11: 154376 | D11: =SUM(C9:C11) -> 521799 | G11: 2765.58 | H11: 41.24 | I11: =G11/H11 -> 67.060621 | J11: =C11*G11/1000000 -> 426.93918 | K11: =SUM(J9:J11) -> 1516.6762 | L11: =_xll.RasFinancial($A$2,A9,3120,"XI_29","LOCAL",,FALSE(),"AC",,1000000) -> 1821.9636 | M11: =(K11/L11)-1 -> -0.16755955 | N11: =_xll.RasFinancial($A$2,"2025/9M",3120,"XI_29","LOCAL",,FALSE(),"ACO",,1000000)-N8-N5 -> 2013.4418 | O11: =(K11/N11)-1 -> -0.24672458 | T11: =-_xll.RasFinancial($A$2,A9,999010002,"IND_INT_DTL","LOCAL",,FALSE(),"AC",,1000000) -> 1664.3239 | U11: =(-_xll.RasFinancial($A$2,"2025/9M",999010002,"IND_INT_DTL","LOCAL",,FALSE(),"ACO",,1000000)-U8-U5) -> 1843.8901 | V11: =T11/N11 -> 0.82660642 | W11: =L11-T11 -> 157.63968
A12: 2025/4Q | B12: 45931 | C12: 168815 | G12: 2764.54 | H12: 41.75 | I12: =G12/H12 -> 66.216527 | J12: =C12*G12/1000000 -> 466.69582
B13: 45962 | C13: 10617 | G13: 2814.97 | H13: 42.2 | I13: =G13/H13 -> 66.70545 | J13: =C13*G13/1000000 -> 29.886536
B14: 45992 | C14: 215921 | D14: =SUM(C12:C14) -> 395353 | E14: 1675000 | F14: =((D5+D8+D11+D14)/E14)-1 -> 0.022776119 | G14: 3005.44 | H14: 42.61 | I14: =G14/H14 -> 70.533678 | J14: =C14*G14/1000000 -> 648.93761 | K14: =SUM(J12:J14) -> 1145.52 | L14: =_xll.RasFinancial($A$2,$A$12,3120,"XI_29","LOCAL",,FALSE(),"AC",,1000000) -> 1396.2827 | M14: =(K14/L14)-1 -> -0.17959309 | N14: =_xll.RasFinancial($A$2,A12,3120,"XI_29","LOCAL",,FALSE(),"ACO",,1000000) -> 1396.2827 | O14: =(K14/N14)-1 -> -0.17959309 | P14: =(M5+M8+M11+M14)/4 -> -0.24594055 | Q14: =(O5+O8+O11+O14)/4 -> -0.22880305 | T14: =-_xll.RasFinancial($A$2,A12,999010002,"IND_INT_DTL","LOCAL",,FALSE(),"AC",,1000000) -> 1352.5447 | U14: =-_xll.RasFinancial($A$2,A12,999010002,"IND_INT_DTL","LOCAL",,FALSE(),"ACO",,1000000) -> 1352.5447 | V14: =T14/N14 -> 0.96867544 | W14: =L14-T14 -> 43.737945
A15: 2026/1Q | B15: 46023 | C15: 199832 | G15: 2929.4 | H15: 43.14 | I15: =G15/H15 -> 67.904497 | J15: =C15*G15/1000000 -> 585.38786
B16: 46054 | C16: 160326 | G16: 2141.92 | H16: 43.61 | I16: =G16/H16 -> 49.115341 | J16: =C16*G16/1000000 -> 343.40547
B17: 46082 | C17: 182527 | D17: =SUM(C15:C17) -> 542685 | G17: 1726.85 | H17: 44.1 | I17: =G17/H17 -> 39.157596 | J17: =C17*G17/1000000 -> 315.19675 | K17: =SUM(J15:J17) -> 1243.9901 | R17: =K17/(1+P14) -> 1649.7241 | S17: =K17/(1+Q14) -> 1613.064 | T17: =R17*V17 -> 1623.4489 | V17: =(V5+V8+V14+V11)/4 -> 0.98407296 | W17: =R17-T17 -> 26.275228
C19: 688
A20: CATES | C20: Çatalağzı Termik Santrali | E20: Faaliyet Rapor Üretim Verisi (MWh) | F20: Yıllık Bazda Sapma Oranı | G20: PTF Ağırlıklı Ort (MWh/TL) | H20: Aylık Ort Dolar Kuru | I20: PTF Ağırlıklı Ort (MWh/USD) | J20: PTF Ağırlıklı Ort Ciro Tahmin(Milyon TL) | L20: Ciro (Milyon TL) | M20: Ciro Sapma | N20: Ciro EM Hariç (Milyon TL) | O20: Ciro EM Hariç Sapma | P20: Ortalama Ciro Sapma Oranı | Q20: Ortalama EM Hariç Ciro Sapma Oranı | R20: Ciro Tahmini (Milyon TL) | S20: EM Hariç Ciro Tahmini (Milyon TL) | T20: COGS (Milyon TL) | U20: EM Hariç COGS (Milyon TL) | V20: Average COGS per Unit | W20: Gross Profit (Milyon TL)
A21: 2025/1Q | B21: 45658 | C21: 183193 | G21: 2537.99 | H21: 35.48 | I21: =G21/H21 -> 71.532976 | J21: =C21*G21/1000000 -> 464.942
B22: 45689 | C22: 143519 | G22: 2506.77 | H22: 36.12 | I22: =G22/H22 -> 69.401163 | J22: =C22*G22/1000000 -> 359.76912
B23: 45717 | C23: 141519 | D23: =SUM(C21:C23) -> 468231 | G23: 2207.18 | H23: 37.04 | I23: =G23/H23 -> 59.589093 | J23: =C23*G23/1000000 -> 312.35791 | K23: =SUM(J21:J23) -> 1137.069 | L23: =_xll.RasFinancial($A$20,A21,3120,"XI_29","LOCAL",,FALSE(),"AC",,1000000) -> 1663.1871 | M23: =(K23/L23)-1 -> -0.31633128 | N23: =_xll.RasFinancial($A$20,"2025/3M",3120,"XI_29","LOCAL",,FALSE(),"ACO",,1000000) -> 1270.8903 | O23: =(K23/N23)-1 -> -0.10529727 | T23: =-_xll.RasFinancial($A$20,A21,999010002,"IND_INT_DTL","LOCAL",,FALSE(),"AC",,1000000) -> 1526.2361 | U23: =-_xll.RasFinancial(A20,"2025/3M",999010002,"IND_INT_DTL","LOCAL",,FALSE(),"ACO",,1000000) -> 1166.242 | V23: =T23/N23 -> 1.2009188 | W23: =L23-T23 -> 136.95101
A24: 2025/2Q | B24: 45748 | C24: 109988 | G24: 2489.25 | H24: 38.05 | I24: =G24/H24 -> 65.420499 | J24: =C24*G24/1000000 -> 273.78763
B25: 45778 | C25: 193369 | G25: 2474.98 | H25: 38.72 | I25: =G25/H25 -> 63.919938 | J25: =C25*G25/1000000 -> 478.58441
B26: 45809 | C26: 151062 | D26: =SUM(C24:C26) -> 454419 | G26: 2240.61 | H26: 39.37 | I26: =G26/H26 -> 56.911608 | J26: =C26*G26/1000000 -> 338.47103 | K26: =SUM(J24:J26) -> 1090.8431 | L26: =_xll.RasFinancial($A$20,A24,3120,"XI_29","LOCAL",,FALSE(),"AC",,1000000) -> 1262.5147 | M26: =(K26/L26)-1 -> -0.13597595 | N26: =(_xll.RasFinancial($A$20,"2025/6M",3120,"XI_29","LOCAL",,FALSE(),"ACO",,1000000))-N23 -> 1338.8535 | O26: =(K26/N26)-1 -> -0.18524094 | T26: =-_xll.RasFinancial($A$20,A24,999010002,"IND_INT_DTL","LOCAL",,FALSE(),"AC",,1000000) -> 1236.2382 | U26: =(-_xll.RasFinancial($A$20,"2025/6M",999010002,"IND_INT_DTL","LOCAL",,FALSE(),"ACO",,1000000)-U23) -> 1306.2911 | V26: =T26/N26 -> 0.92335583 | W26: =L26-T26 -> 26.276479
A27: 2025/3Q | B27: 45839 | C27: 188065 | G27: 2981.73 | H27: 40.14 | I27: =G27/H27 -> 74.283259 | J27: =C27*G27/1000000 -> 560.75905
B28: 45870 | C28: 210270 | G28: 2952.26 | H28: 40.75 | I28: =G28/H28 -> 72.448098 | J28: =C28*G28/1000000 -> 620.77171
B29: 45901 | C29: 182893 | D29: =SUM(C27:C29) -> 581228 | G29: 2765.58 | H29: 41.24 | I29: =G29/H29 -> 67.060621 | J29: =C29*G29/1000000 -> 505.80522 | K29: =SUM(J27:J29) -> 1687.336 | L29: =_xll.RasFinancial($A$20,A27,3120,"XI_29","LOCAL",,FALSE(),"AC",,1000000) -> 1815.6112 | M29: =(K29/L29)-1 -> -0.070651273 | N29: =_xll.RasFinancial(A20,"2025/9M",3120,"XI_29","LOCAL",,FALSE(),"ACO",,1000000)-N26-N23 -> 2011.4564 | O29: =(K29/N29)-1 -> -0.16113717 | T29: =-_xll.RasFinancial($A$20,A27,999010002,"IND_INT_DTL","LOCAL",,FALSE(),"AC",,1000000) -> 1456.9503 | U29: =(-_xll.RasFinancial($A$20,"2025/9M",999010002,"IND_INT_DTL","LOCAL",,FALSE(),"ACO",,1000000)-U26-U23) -> 1642.4986 | V29: =T29/N29 -> 0.72432607 | W29: =L29-T29 -> 358.66093
A30: 2025/4Q | B30: 45931 | C30: 173700 | G30: 2764.54 | H30: 41.75 | I30: =G30/H30 -> 66.216527 | J30: =C30*G30/1000000 -> 480.2006
B31: 45962 | C31: 173792 | G31: 2814.97 | H31: 42.2 | I31: =G31/H31 -> 66.70545 | J31: =C31*G31/1000000 -> 489.21927
B32: 45992 | C32: 182006 | D32: =SUM(C30:C32) -> 529498 | E32: 2034000 | F32: =((D23+D26+D29+D32)/E32)-1 -> -0.00030678466 | G32: 3005.44 | H32: 42.61 | I32: =G32/H32 -> 70.533678 | J32: =C32*G32/1000000 -> 547.00811 | K32: =SUM(J30:J32) -> 1516.428 | L32: =_xll.RasFinancial($A$20,A30,3120,"XI_29","LOCAL",,FALSE(),"AC",,1000000) -> 1677.2904 | M32: =(K32/L32)-1 -> -0.095906141 | N32: =_xll.RasFinancial($A$20,A30,3120,"XI_29","LOCAL",,FALSE(),"ACO",,1000000) -> 1677.2904 | O32: =(K32/N32)-1 -> -0.095906141 | P32: =(M23+M26+M29+M32)/4 -> -0.15471616 | Q32: =(O23+O26+O29+O32)/4 -> -0.13689538 | T32: =-_xll.RasFinancial($A$20,A30,999010002,"IND_INT_DTL","LOCAL",,FALSE(),"AC",,1000000) -> 1571.2469 | U32: =-_xll.RasFinancial($A$20,A12,999010002,"IND_INT_DTL","LOCAL",,FALSE(),"ACO",,1000000) -> 1571.2469 | V32: =T32/N32 -> 0.93677688 | W32: =L32-T32 -> 106.04354
A33: 2026/1Q | B33: 46023 | C33: 107354 | G33: 2929.4 | H33: 43.14 | I33: =G33/H33 -> 67.904497 | J33: =C33*G33/1000000 -> 314.48281
B34: 46054 | C34: 142725 | G34: 2141.92 | H34: 43.61 | I34: =G34/H34 -> 49.115341 | J34: =C34*G34/1000000 -> 305.70553
B35: 46082 | C35: 110529 | D35: =SUM(C33:C35) -> 360608 | G35: 1726.85 | H35: 44.1 | I35: =G35/H35 -> 39.157596 | J35: =C35*G35/1000000 -> 190.867 | K35: =SUM(J33:J35) -> 811.05534 | R35: =K35/(1+P32) -> 959.50651 | S35: =K35/(1+Q32) -> 939.69529 | T35: =R35*V35 -> 908.02362 | V35: =(V23+V26+V32+V29)/4 -> 0.94634441 | W35: =R35-T35 -> 51.482891
C37: 1673 | D37: 1011 | E37: 3125 | F37: 652 | G37: 1217 | H37: 1189 | I37: 1798 | J37: 1797 | K37: 1519
A38: AKENR | C38: Erzin DGKÇS | D38: Bulam HES | E38: Burç Bendi HES | F38: Uluabat HES | G38: Feke I HES | H38: Feke II HES | I38: Gökkaya HES | J38: Himmetli HES | K38: Ayyıldız RES | M38: Faaliyet Rapor Üretim Verisi (MWh) | N38: Yıllık Bazda Sapma Oranı | O38: PTF Ağırlıklı Ort (MWh/TL) | P38: Aylık Ort Dolar Kuru | Q38: PTF Ağırlıklı Ort (MWh/USD) | R38: Ciro Tahmini (PTF ve YEKDEM) (Milyon TL) | T38: Ciro (Milyon TL) | U38: Ciro Sapma | V38: Ciro EM Hariç (Milyon TL) | W38: Ciro EM Hariç Sapma | X38: Ortalama Ciro Sapma Oranı | Y38: Ortalama EM Hariç Ciro Sapma Oranı | Z38: Ciro Tahmini (Milyon TL) | AA38: EM Hariç Ciro Tahmini (Milyon TL)
A39: 2025/1Q | B39: 45658 | C39: 400037.23 | D39: 1165.21 | E39: 0 | F39: 8643.75 | G39: 3911 | H39: 4782.9 | I39: 3808 | J39: 3599 | K39: 6766.96 | O39: 2537.99 | P39: 35.48 | Q39: =O39/P39 -> 71.532976 | R39: =AKENR!G53/1000000 -> 1099.867
B40: 45689 | C40: 284543.7 | D40: 966.98 | E40: 0 | F40: 11619.11 | G40: 3502 | H40: 4555.27 | I40: 3718 | J40: 3254 | K40: 7403.36 | O40: 2506.77 | P40: 36.12 | Q40: =O40/P40 -> 69.401163 | R40: =AKENR!H53/1000000 -> 802.5566
B41: 45717 | C41: 251002.18 | D41: 1690.95 | E41: 2700.53 | F41: 5759.52 | G41: 4800 | H41: 5869.53 | I41: 4357.39 | J41: 4230.94 | K41: 7575.27 | L41: =SUM(C39:K41) -> 1040262.8 | O41: 2207.18 | P41: 37.04 | Q41: =O41/P41 -> 59.589093 | R41: =AKENR!I53/1000000 -> 637.46069 | S41: =SUM(R39:R41) -> 2539.8843 | T41: =_xll.RasFinancial($A$38,A39,3120,"XI_29","LOCAL",,FALSE(),"AC",,1000000) -> 6638.233 | U41: =(S41/T41)-1 -> -0.61738548 | V41: =_xll.RasFinancial($A$38,"2025/3M",3120,"XI_29","LOCAL",,FALSE(),"ACO",,1000000) -> 5072.563 | W41: =(S41/V41)-1 -> -0.49928974
A42: 2025/2Q | B42: 45748 | C42: 164507.24 | D42: 2822.49 | E42: 6169.64 | F42: 2251.75 | G42: 9506 | H42: 11286.68 | I42: 7472 | J42: 8393 | K42: 5934.37 | O42: 2489.25 | P42: 38.05 | Q42: =O42/P42 -> 65.420499 | R42: =AKENR!J53/1000000 -> 544.50354
...

Sheet PTF
A1: TL | B1: 1A25 | C1: 2A25 | D1: 3A25 | E1: 4A25 | F1: 5A25 | G1: 6A25 | H1: 7A25 | I1: 8A25 | J1: 9A25 | K1: 10A25 | L1: 11A25 | M1: 12A25 | N1: 1A26 | O1: 2A26 | P1: 3A26 | Q1: 4A26 | R1: 5A26 | S1: 6A26
A2: PTF FİYATI | B2: 2537.99 | C2: 2506.77 | D2: 2207.18 | E2: 2489.25 | F2: 2474.98 | G2: 2240.61 | H2: 2981.73 | I2: 2952.26 | J2: 2765.58 | K2: 2764.54 | L2: 2814.97 | M2: 3005.44 | N2: 2929.4 | O2: 2141.92 | P2: 1726.85 | Q2: 1068.43 | R2: 795.7 | S2: 1341.48
A4: AYLIK ORT | B4: 1A25 | C4: 2A25 | D4: 3A25 | E4: 4A25 | F4: 5A25 | G4: 6A25 | H4: 7A25 | I4: 8A25 | J4: 9A25 | K4: 10A25 | L4: 11A25 | M4: 12A25 | N4: 1A26 | O4: 2A26 | P4: 3A26 | Q4: 4A26 | R4: 5A26 | S4: 6A26
A5: DOLAR | B5: 35,48 | C5: 36.12 | D5: 37.04 | E5: 38.05 | F5: 38.72 | G5: 39.37 | H5: 40.14 | I5: 40.75 | J5: 41.24 | K5: 41.75 | L5: 42.2 | M5: 42.61 | N5: 43.14 | O5: 43.61 | P5: 44.1 | Q5: 44.68 | R5: 45.36 | S5: 46.17
A7: DOLAR | B7: 1A25 | C7: 2A25 | D7: 3A25 | E7: 4A25 | F7: 5A25 | G7: 6A25 | H7: 7A25 | I7: 8A25 | J7: 9A25 | K7: 10A25 | L7: 11A25 | M7: 12A25 | N7: 1A26 | O7: 2A26 | P7: 3A26 | Q7: 4A26 | R7: 5A26 | S7: 6A26
A8: PTF FİYATI | B8: 71.64 | C8: 69.53 | D8: 59.76 | E8: 65.54 | F8: 64.03 | G8: 56.95 | H8: 74.36 | I8: 72.53 | J8: 67.13 | K8: 66.28 | L8: 66.79 | M8: 70.6 | N8: 68 | O8: 49.19 | P8: 39.23 | Q8: 23.96 | R8: 17.57 | S8: 29.08

Sheet Sayfa1
A1: ŞİRKET | B1: SANTRAL | C1: KURULU GÜÇ(MW) | D1: SATIŞ TÜRÜ | E1: ÜRETİM VERİSİ
A2: A1YEN | B2: Adala Ges | C2: 2.09 | D2: YEKDEM | E2: X
B3: Attalos GES | C3: 1.14 | D3: YEKDEM | E3: X
B4: Dombaylı GES | C4: 9.65 | D4: YEKDEM | E4: X
B5: Esenyazı GES | C5: 4.56 | D5: YEKDEM | E5: X
B6: Başıbüyük GES | C6: 10.26 | D6: YEKDEM | E6: X
B7: Çorbacılar GES | C7: 2.8 | D7: YEKDEM | E7: X
B8: İmamdamı 1 GES | C8: 6.58 | D8: YEKDEM | E8: X
B9: İmamdamı 2 GES | C9: 2.24 | D9: YEKDEM | E9: X
B10: Ağzıkarahan GES | C10: 2.39 | D10: YEKDEM | E10: X
B11: Alanya GES | C11: 4.75 | D11: YEKDEM | E11: X
B12: Çubuk GES | C12: 4.7 | D12: YEKDEM | E12: X
B13: Yunak GES | C13: =C14-SUM(C2:C12) -> 2.25 | D13: YEKDEM | E13: X
B14: Toplam | C14: 53.41
A16: AKENR | B16: =AKENR!A2 -> Erzin DGKÇS | C16: 904 | D16: PTF | E16: E
B17: =AKENR!A3 -> Bulam HES | C17: 7 | D17: YEKDEM | E17: E
B18: =AKENR!A4 -> Burç Bendi HES | C18: 28 | D18: YEKDEM | E18: E
B19: =AKENR!A5 -> Uluabat HES | C19: 100 | D19: YEKDEM | E19: E
B20: =AKENR!A6 -> Feke I HES | C20: 30 | D20: YEKDEM | E20: E
B21: =AKENR!A7 -> Feke II HES | C21: 70 | D21: YEKDEM | E21: E
B22: =AKENR!A8 -> Gökkaya HES | C22: 30 | D22: YEKDEM | E22: E
B23: =AKENR!A9 -> Himmetli HES | C23: 27 | D23: YEKDEM | E23: E
B24: =AKENR!A10 -> Ayyıldız RES | C24: 28 | D24: YEKDEM | E24: E
B25: =AKENR!A11 -> Toplam | C25: 1224
A27: AKFYE | B27: Sırma HES | C27: 6.66 | D27: PTF | E27: E
B28: Çamlıca III HES | C28: 28.48 | D28: PTF | E28: E
B29: Saraçbendi HES | C29: 26.28 | D29: PTF | E29: E
B30: Otluca HES | C30: 48.77 | D30: PTF | E30: E
B31: Demirciler HES | C31: 8.7 | D31: PTF | E31: E
B32: Yağmur HES | C32: 9.19 | D32: PTF | E32: E
B33: Kavakçalı HES | C33: 11.45 | D33: PTF | E33: E
B34: Gelinkaya HES | C34: 7.08 | D34: PTF | E34: E
B35: Doğançay HES | C35: 31.61 | D35: PTF | E35: E
B36: Doruk HES | C36: 28.89 | D36: PTF | E36: E
B37: Sekiyaka HES | C37: 3.53 | D37: PTF | E37: E
B38: Çalıkobası HES | C38: 18.11 | D38: YEKDEM | E38: E
B39: Solentegre GES | C39: 9.62 | D39: YEKDEM | E39: E
... B62: Demirciler Hibrit GES | C62: 13.26 | D62: YEKDEM | E62: X
B63: Toplam | C63: 886.54 | D63: YEKDEM
A65: AKSEN | B65: Aksa Enerji Doğalgaz | C65: 900 | D65: PTF | E65: E
...

Sheet A1YEN
A1: SANTRAL ADI | B1: KURULU GÜCÜ | C1: EIC KODU | D1: ID
A2: Adala Ges | B2: 2.09
A3: Attalos GES | B3: 1.14
A4: Dombaylı GES | B4: 9.65
A5: Esenyazı GES | B5: 4.56
A6: Başıbüyük GES | B6: 10.26
A7: Çorbacılar GES | B7: 2.8
A8: İmamdamı 1 GES | B8: 6.58
A9: İmamdamı 2 GES | B9: 2.24
A10: Ağzıkarahan GES | B10: 2.39
A11: Alanya GES | B11: 4.75
A12: Çubuk GES | B12: 4.7
A13: Yunak GES | B13: =B14-SUM(B2:B12) -> 2.25
A14: Toplam | B14: 53.41

Sheet AKENR
A1: SANTRAL ADI | B1: KURULU GÜCÜ | C1: EIC KODU | D1: ID | E1: SATIŞ FİYATI | F1: SÜRE (YIL SONU) | G1: 1A25 | H1: 2A25 | I1: 3A25 | J1: 4A25 | K1: 5A25 | L1: 6A25 | M1: 7A25 | N1: 8A25 | O1: 9A25 | P1: 10A25 | Q1: 11A25 | R1: 12A25 | S1: 1A26 | T1: 2A26 | U1: 3A26 | V1: 4A26 | W1: 5A26 | X1: 6A26
A2: Erzin DGKÇS | B2: 904 | C2: 40W000000007585S | D2: 1673 | E2: PTF | F2: - | G2: 400037.23 | H2: 284543.7 | I2: 251002.18 | J2: 164507.24 | K2: 130665.2 | L2: 151221.43 | M2: 210865.88 | N2: 191539.2 | O2: 363545.78 | P2: 398333.23 | Q2: 337624.58 | R2: 400834.83 | S2: 444596.71 | T2: 113240.34 | U2: 0 | V2: 46.59 | W2: 251.89 | X2: 1403.1
A3: Bulam HES | B3: 7 | C3: 40W000000003383N | D3: 1011 | E3: PTF | F3: - | G3: 1165.21 | H3: 966.98 | I3: 1690.95 | J3: 2822.49 | K3: 2133.99 | L3: 796.28 | M3: 492.84 | N3: 402.68 | O3: 358.14 | P3: 497.97 | Q3: 546.92 | R3: 792.59 | S3: 775.46 | T3: 3337.11 | U3: 3742.39 | V3: 2633.31 | W3: 1493.32 | X3: 2882.7
A4: Burç Bendi HES | B4: 28 | C4: 40W000000004082W | D4: 3125 | E4: PTF | F4: - | G4: 0 | H4: 0 | I4: 2700.53 | J4: 6169.64 | K4: 3137.59 | L4: 1574.46 | M4: 1160.8 | N4: 630.31 | O4: 688.54 | P4: 1063.72 | Q4: 1263.52 | R4: 1742.25 | S4: 3195.31 | T4: 14388.2 | U4: 13772.51 | V4: 13637.23 | W4: 7465.76 | X4: 8277.55
A5: Uluabat HES | B5: 100 | C5: 40W0000000040621 | D5: 652 | E5: PTF | F5: - | G5: 8643.75 | H5: 11619.11 | I5: 5759.52 | J5: 2251.75 | K5: 13375.12 | L5: 6365.73 | M5: 7500.2 | N5: 10145.38 | O5: 1379.58 | P5: 0 | Q5: 0 | R5: 3206.49 | S5: 32496.04 | T5: 53189.04 | U5: 56636.1 | V5: 51916.8 | W5: 47995.98 | X5: 26788.3
A6: Feke I HES | B6: 30 | C6: 40W000000005631K | D6: 1217 | E6: PTF | F6: - | G6: 3911 | H6: 3502 | I6: 4800 | J6: 9506 | K6: 6984 | L6: 4320 | M6: 3315 | N6: 3089 | O6: 2919 | P6: 3111 | Q6: 3208 | R6: 3356 | S6: 4495 | T6: 13952 | U6: 15838 | V6: 14718 | W6: 10905 | X6: 10078
A7: Feke II HES | B7: 70 | C7: 40W000000004345Q | D7: 1189 | E7: PTF | F7: - | G7: 4782.9 | H7: 4555.27 | I7: 5869.53 | J7: 11286.68 | K7: 8553.81 | L7: 3225.31 | M7: 5591.23 | N7: 3548.36 | O7: 3391.35 | P7: 2451.1 | Q7: 5079.49 | R7: 3190.25 | S7: 6945.33 | T7: 32610.49 | U7: 28654.2 | V7: 38314.8 | W7: 27316.88 | X7: 13708.4
A8: Gökkaya HES | B8: 30 | C8: 40W000000005555A | D8: 1798 | E8: PTF | F8: - | G8: 3808 | H8: 3718 | I8: 4357.39 | J8: 7472 | K8: 6110 | L8: 4064 | M8: 3347 | N8: 2882 | O8: 2731 | P8: 2865 | Q8: 2888 | R8: 3145 | S8: 3776 | T8: 14205.4 | U8: 16125 | V8: 16137.1 | W8: 11580.22 | X8: 9820
A9: Himmetli HES | B9: 27 | C9: 40W000000008278W | D9: 1797 | E9: PTF | F9: - | G9: 3599 | H9: 3254 | I9: 4230.94 | J9: 8393 | K9: 6174 | L9: 3832 | M9: 2805.5 | N9: 2600 | O9: 2429 | P9: 2436.5 | Q9: 2599 | R9: 2781 | S9: 3664.51 | T9: 14505 | U9: 16101 | V9: 15260 | W9: 11032 | X9: 9978
A10: Ayyıldız RES | B10: 28 | C10: 40W000000000761W | D10: 1519 | E10: PTF | F10: - | G10: 6766.96 | H10: 7403.36 | I10: 7575.27 | J10: 5934.37 | K10: 4363.11 | L10: 5430.04 | M10: 8760.72 | N10: 13264.23 | O10: 8796.3 | P10: 4235.96 | Q10: 5651.19 | R10: 4361.45 | S10: 11242.27 | T10: 7319.19 | U10: 7876.2 | V10: 4121.56 | W10: 1016.45 | X10: 5693.72
A11: Toplam | B11: =SUM(B2:B10) -> 1224 | G11: 432714.05 | H11: 319562.42 | I11: 287986.31 | J11: 218343.17 | K11: 181496.82 | L11: 180829.25 | M11: 243839.17 | N11: 228101.16 | O11: 386238.69 | P11: 414994.48 | Q11: 358860.7 | R11: 423409.86 | S11: 511186.63 | T11: 266746.77 | U11: 158745.4 | V11: 156785.39 | W11: 119057.5 | X11: 88629.77
A14: HES Geçen Yılın Aynı Dönemine Göre Değişim | S14: =(SUM(S3:S9)/SUM(G3:G9))-1 -> 1.1361617 | T14: =(SUM(T3:T9)/SUM(H3:H9))-1 -> 4.2936931 | U14: =(SUM(U3:U9)/SUM(I3:I9))-1 -> 4.1300594 | V14: =(SUM(V3:V9)/SUM(J3:J9))-1 -> 2.1860599 | W14: =(SUM(W3:W9)/SUM(K3:K9))-1 -> 1.5348168 | X14: =(SUM(X3:X9)/SUM(L3:L9))-1 -> 2.3722265
A15: HES Kümülatif Değişim | T15: =((SUM(S3:T9))/(SUM(G3:H9)))-1 -> 2.7652324 | U15: =((SUM(S3:U9))/(SUM(G3:I9)))-1 -> 3.2492072 | V15: =((SUM(S3:V9))/(SUM(G3:J9)))-1 -> 2.8599676 | W15: =((SUM(S3:W9))/(SUM(G3:K9)))-1 -> 2.5126673 | X15: =((SUM(S3:X9))/(SUM(G3:L9)))-1 -> 2.4958144
A16: RES Geçen Yılın Aynı Dönemine Göre Değişim | S16: =(S10/G10)-1 -> 0.66134719 | T16: =(T10/H10)-1 -> -0.011369162 | U16: =(U10/I10)-1 -> 0.039725317 | V16: =(V10/J10)-1 -> -0.3054764 | W16: =(W10/K10)-1 -> -0.76703544 | X16: =(X10/L10)-1 -> 0.048559495
A17: RES Kümülatif Değişim | T17: =(SUM(S10:T10)/SUM(G10:H10))-1 -> 0.30988291 | U17: =(SUM(S10:U10)/SUM(G10:I10))-1 -> 0.21577111 | V17: =(SUM(S10:V10)/SUM(G10:J10))-1 -> 0.10401966 | W17: =(SUM(S10:W10)/SUM(G10:K10))-1 -> -0.014586617 | X17: =(SUM(S10:X10)/SUM(G10:L10))-1 -> -0.0054364316
A18: DGKÇS Geçen Yılın Aynı Dönemine Göre Değişim | S18: =(S2/G2)-1 -> 0.11138833 | T18: =(T2/H2)-1 -> -0.6020283 | U18: =(U2/I2)-1 -> -1 | V18: =(V2/J2)-1 -> -0.99971679 | W18: =(W2/K2)-1 -> -0.99807225 | X18: =(X2/L2)-1 -> -0.99072155
A19: DGKÇS Kümülatif Değişim | T19: =(SUM(S2:T2)/SUM(G2:H2))-1 -> -0.18514083 | U19: =(SUM(S2:U2)/SUM(G2:I2))-1 -> -0.40375468 | V19: =(SUM(S2:V2)/SUM(G2:J2))-1 -> -0.49287471 | W19: =(SUM(S2:W2)/SUM(G2:K2))-1 -> -0.54650984 | X19: =(SUM(S2:X2)/SUM(G2:L2))-1 -> -0.59511726
A20: Toplamın Geçen Yılın Aynı Dönemine Göre Değişimi | S20: =(S11/G11)-1 -> 0.18134974 | T20: =(T11/H11)-1 -> -0.16527491 | U20: =(U11/I11)-1 -> -0.44877449 | V20: =(V11/J11)-1 -> -0.28193133 | W20: =(W11/K11)-1 -> -0.34402432 | X20: =(X11/L11)-1 -> -0.50987039
A21: Toplam Kümülatif Değişimi | T21: =(SUM(S11:T11)/SUM(G11:H11))-1 -> 0.034105719 | U21: =(SUM(S11:U11)/SUM(G11:I11))-1 -> -0.099574821 | V21: =(SUM(S11:V11)/SUM(G11:J11))-1 -> -0.13121006 | W21: =(SUM(S11:W11)/SUM(G11:K11))-1 -> -0.15803114 | X21: =(SUM(S11:X11)/SUM(G11:L11))-1 -> -0.19728191
A23: SANTRALLERİN DOLAR BAZLI GELİRLERİ | B23: Sütun1 | C23: Sütun2 | D23: Sütun3 | E23: Sütun4 | F23: Sütun5 | G23: 1A25 | H23: 2A25 | I23: 3A25 | J23: 4A25 | K23: 5A25 | L23: 6A25 | M23: 7A25 | N23: 8A25 | O23: 9A25 | P23: 10A25 | Q23: 11A25 | R23: 12A25 | S23: 1A26 | T23: 2A26 | U23: 3A26 | V23: 4A26 | W23: 5A26 | X23: 6A26
A24: Erzin DGKÇS | G24: =G41*G2 -> 28658667 | H24: =H41*H2 -> 19784323 | I24: =I41*I2 -> 14999890 | J24: =J41*J2 -> 10781805 | K24: =K41*K2 -> 8366492.8 | L24: =L41*L2 -> 8612060.4 | M24: =M41*M2 -> 15679987 | N24: =N41*N2 -> 13892338 | ... X24: =X41*X2 -> 40802.148
A25: Bulam HES | G25: =G41*G3 -> 83475.644 | H25: =H41*H3 -> 67234.119 | I25: =I41*I3 -> 101051.17 | J25: =J41*J3 -> 184985.99 | K25: =K41*K3 -> 136639.38 | L25: =L41*L3 -> 45348.146 | M25: =M41*M3 -> 36647.582 | N25: =N41*N3 -> 29206.38 | ... X25: =X41*X3 -> 83828.916
A26: Burç Bendi HES | G26: =G41*G4 -> 0 | H26: =H41*H4 -> 0 | I26: =I41*I4 -> 161383.67 | J26: =J41*J4 -> 404358.21 | K26: =K41*K4 -> 200899.89 | L26: =L41*L4 -> 89665.497 | M26: =M41*M4 -> 86317.088 | N26: =N41*N4 -> 45716.384 | ... X26: =X41*X4 -> 240711.15
A27: Uluabat HES | G27: =G41*G5 -> 619238.25 | H27: =H41*H5 -> 807876.72 | I27: =I41*I5 -> 344188.92 | J27: =J41*J5 -> 147579.7 | K27: =K41*K5 -> 856408.93 | L27: =L41*L5 -> 362528.32 | M27: =M41*M5 -> 557714.87 | N27: =N41*N5 -> 735844.41 | ... X27: =X41*X5 -> 779003.76
A28: Feke I HES | G28: =G41*G6 -> 280184.04 | H28: =H41*H6 -> 243494.06 | I28: =I41*I6 -> 286848 | J28: =J41*J6 -> 623023.24 | K28: =K41*K6 -> 447185.52 | L28: =L41*L6 -> 246024 | M28: =M41*M6 -> 246503.4 | N28: =N41*N6 -> 224045.17 | ... X28: =X41*X6 -> 293068.24
A29: Feke II HES | G29: =G41*G7 -> 342646.96 | H29: =H41*H7 -> 316727.92 | I29: =I41*I7 -> 350763.11 | J29: =J41*J7 -> 739729.01 | K29: =K41*K7 -> 547700.45 | L29: =L41*L7 -> 183681.4 | M29: =M41*M7 -> 415763.86 | N29: =N41*N7 -> 257362.55 | ... X29: =X41*X7 -> 398640.27
A30: Gökkaya HES | G30: =G41*G8 -> 272805.12 | H30: =H41*H8 -> 258512.54 | I30: =I41*I8 -> 260397.63 | J30: =J41*J8 -> 489714.88 | K30: =K41*K8 -> 391223.3 | L30: =L41*L8 -> 231444.8 | M30: =M41*M8 -> 248882.92 | N30: =N41*N8 -> 209031.46 | ... X30: =X41*X8 -> 285565.6
A31: Himmetli HES | G31: =G41*G9 -> 257832.36 | H31: =H41*H9 -> 226250.62 | I31: =I41*I9 -> 252840.97 | J31: =J41*J9 -> 550077.22 | K31: =K41*K9 -> 395321.22 | L31: =L41*L9 -> 218232.4 | M31: =M41*M9 -> 208616.98 | N31: =N41*N9 -> 188578 | ... X31: =X41*X9 -> 290160.24
A32: Ayyıldız RES | G32: =G41*G10 -> 484785.01 | H32: =H41*H10 -> 514755.62 | I32: =I41*I10 -> 452698.14 | J32: =J41*J10 -> 388938.61 | K32: =K41*K10 -> 279369.93 | L32: =L41*L10 -> 309240.78 | M32: =M41*M10 -> 651447.14 | N32: =N41*N10 -> 962054.6 | ... X32: =X41*X10 -> 165573.38
A33: Toplam | G33: =G41*G11 -> 30999635 | H33: =SUM(H24:H32) -> 22219175 | I33: =SUM(I24:I32) -> 17210062 | J33: =SUM(J24:J32) -> 14310211 | K33: =SUM(K24:K32) -> 11621241 | L33: =SUM(L24:L32) -> 10298226 | M33: =SUM(M24:M32) -> 18131881 | N33: =SUM(N24:N32) -> 16544177 | O33: =SUM(O24:O32) -> 25928203 | ... X33: =SUM(X24:X32) -> 2577353.7
A35: ÇEYREKLİK GELİR | I35: =G33+H33+I33 -> 70428871 | L35: =J33+K33+L33 -> 36229679 | O35: =M33+N33+O33 -> 60604261 | R35: =P33+Q33+R33 -> 81366876 | U35: =S33+T33+U33 -> 54109546 | X35: =V33+W33+X33 -> 8425771.9
A36: ÖNCEKİ ÇEYREĞE GÖRE DEĞİŞİM | L36: =(L35/I35)-1 -> -0.48558485 | O36: =(O35/L35)-1 -> 0.67277943 | R36: =(R35/O35)-1 -> 0.34259333 | U36: =(U35/R35)-1 -> -0.33499295 | X36: =(X35/U35)-1 -> -0.84428308
A37: GEÇEN YILIN AYNI DÖNEMİNE GÖRE DEĞİŞİM | U37: =(U35/I35)-1 -> -0.23171357 | X37: =(X35/L35)-1 -> -0.76743454
A40: DOLAR | G40: 1A25 | H40: 2A25 | I40: 3A25 | J40: 4A25 | K40: 5A25 | L40: 6A25 | M40: 7A25 | N40: 8A25 | O40: 9A25 | P40: 10A25 | Q40: 11A25 | R40: 12A25 | S40: 1A26 | T40: 2A26 | U40: 3A26 | V40: 4A26 | W40: 5A26 | X40: 6A26
A41: PTF FİYATI | G41: =PTF!B8 -> 71.64 | H41: =PTF!C8 -> 69.53 | I41: =PTF!D8 -> 59.76 | J41: =PTF!E8 -> 65.54 | K41: =PTF!F8 -> 64.03 | L41: =PTF!G8 -> 56.95 | M41: =PTF!H8 -> 74.36 | N41: =PTF!I8 -> 72.53 | ... X41: =PTF!S8 -> 29.08
A43: SANTRALLERİN TL BAZLI GETİRİLERİ | B43: Sütun1 | C43: Sütun2 | D43: Sütun3 | E43: Sütun4 | F43: Sütun5 | G43: 1A25 | H43: 2A25 | I43: 3A25 | J43: 4A25 | K43: 5A25 | L43: 6A25 | M43: 7A25 | N43: 8A25 | O43: 9A25 | P43: 10A25 | Q43: 11A25 | R43: 12A25 | S43: 1A26 | T43: 2A26 | U43: 3A26 | V43: 4A26 | W43: 5A26 | X43: 6A26
A44: Erzin DGKÇS | G44: =$G$60*G24 -> 1.0168095e+09 | H44: =$H$60*H24 -> 7.1460976e+08 | I44: =$I$60*I24 -> 5.5559594e+08 | J44: =$J$60*J24 -> 4.1024766e+08 | K44: =$K$60*K24 -> 3.239506e+08 | L44: =$L$60*L24 -> 3.3905682e+08 | M44: =$M$60*M24 -> 6.2939467e+08 | N44: =$N$60*N24 -> 5.6611278e+08 | O44: =$O$60*O24 -> 1.0064551e+09 | P44: =$P$60*P24 -> 1.1022637e+09 | Q44: =$Q$60*Q24 -> 9.5160771e+08 | R44: =$R$60*R24 -> 1.2058178e+09 | S44: =$S$60*S24 -> 1.3042333e+09 | T44: =$T$60*T24 -> 2.4292045e+08 | U44: =$U$60*U24 -> 0 | V44: =$V$60*V24 -> 49876.123 | W44: =$W$60*W24 -> 200750.08 | X44: =$X$60*X24 -> 1883835.2
A45: Bulam HES | G45: =$G$60*G25 -> 2961715.9 | H45: =$H$60*H25 -> 2428496.4 | I45: =$I$60*I25 -> 3742935.4 | J45: =$J$60*J25 -> 7038717.1 | K45: =$K$60*K25 -> 5290676.8 | L45: =$L$60*L25 -> 1785356.5 | M45: =$M$60*M25 -> 1471034 | N45: =$N$60*N25 -> 1190160 | O45: =$O$60*O25 -> 991489.53 | P45: =$P$60*P25 -> 1377977.6 | Q45: =$Q$60*Q25 -> 1541514.8 | R45: =$R$60*R25 -> 2384321.5 | S45: =$S$60*S25 -> 2274827.4 | T45: =$T$60*T25 -> 7158687.9 | U45: =$U$60*U25 -> 6474495.6 | V45: =$V$60*V25 -> 2819044.7 | W45: =$W$60*W25 -> 1190139 | X45: =$X$60*X25 -> 3870381.1
A46: Burç Bendi HES | G46: =$G$60*G26 -> 0 | H46: =$H$60*H26 -> 0 | I46: =$I$60*I26 -> 5977651.2 | J46: =$J$60*J26 -> 15385830 | K46: =$K$60*K26 -> 7778843.7 | L46: =$L$60*L26 -> 3530130.6 | M46: =$M$60*M26 -> 3464767.9 | N46: =$N$60*N26 -> 1862942.7 | O46: =$O$60*O26 -> 1906182.5 | P46: =$P$60*P26 -> 2943515.3 | Q46: =$Q$60*Q26 -> 3561279.1 | R46: =$R$60*R26 -> 5241151.4 | S46: =$S$60*S26 -> 9373505.8 | T46: =$T$60*T26 -> 30865220 | U46: =$U$60*U26 -> 23827035 | V46: =$V$60*V26 -> 14599102 | W46: =$W$60*W26 -> 5950025.6 | X46: =$X$60*X26 -> 11113634
A47: Uluabat HES | G47: =$G$60*G27 -> 21970573 | H47: =$H$60*H27 -> 29180507 | I47: =$I$60*I27 -> 12748757 | J47: =$J$60*J27 -> 5615407.4 | K47: =$K$60*K27 -> 33160154 | L47: =$L$60*L27 -> 14272740 | M47: =$M$60*M27 -> 22386675 | N47: =$N$60*N27 -> 29985660 | O47: =$O$60*O27 -> 3819286.1 | P47: =$P$60*P27 -> 0 | Q47: =$Q$60*Q27 -> 0 | R47: =$R$60*R27 -> 9645974.8 | S47: =$S$60*S27 -> 95327783 | T47: =$T$60*T27 -> 1.1409985e+08 | U47: =$U$60*U27 -> 97982888 | V47: =$V$60*V27 -> 55578637 | W47: =$W$60*W27 -> 38251606 | X47: =$X$60*X27 -> 35966604
...

Sheet AKFYE
A1: {=A1:M37SANTRAL ADI} -> #NAME? | B1: KURULU GÜCÜ | C1: EIC KODU | D1: ID | E1: SATIŞ FIYATI | F1: YIL (SENE SONU) | H1: SANTRAL ADI | I1: KURULU GÜCÜ | J1: EIC KODU | K1: ID | L1: SATIŞ FİYATI | M1: SÜRE (YIL SONU) | N1: 1A25 | O1: 2A25 | P1: 3A25 | Q1: 4A25 | R1: 5A25 | S1: 6A25 | T1: 7A25 | U1: 8A25 | V1: 9A25 | W1: 10A25 | X1: 11A25 | Y1: 12A25 | Z1: 1A26 | AA1: 2A26 | AB1: 3A26 | AC1: 4A26 | AD1: 5A26 | AE1: 6A26
A2: Sırma HES | B2: 6.66 | C2: 40W000000000692P | D2: 1479 | E2: PTF | F2: - | H2: Sırma HES | I2: 6.66 | J2: 40W000000000692P | K2: 1479 | L2: PTF | M2: - | N2: 0 | O2: 0 | P2: 0 | Q2: 0 | R2: 0 | S2: 1783.2 | T2: 3565.35 | U2: 236.8 | V2: 0 | W2: 0 | X2: 0 | Y2: 0 | Z2: 0 | AA2: 0 | AB2: 536.7 | AC2: 1481.96 | AD2: 436.65 | AE2: 2303.3
A3: Çamlıca III HES | B3: 28.48 | C3: 40W000000004467C | D3: 919 | E3: PTF | F3: - | H3: Çamlıca III HES | I3: 28.48 | J3: 40W000000004467C | K3: 919 | L3: PTF | M3: - | N3: 1971.1 | O3: 839.8 | P3: 1476.7 | Q3: 1491.4 | R3: 1597.6 | S3: 1327.6 | T3: 988.8 | U3: 1138.3 | V3: 1650.1 | W3: 393.2 | X3: 560.4 | Y3: 735.6 | Z3: 1048.9 | AA3: 4675.5 | AB3: 5132.6 | AC3: 8171.3 | AD3: 12244.67 | AE3: 9130.1
A4: Saraçbendi HES | B4: 26.28 | C4: 40W000000004815F | D4: 920 | E4: PTF | F4: - | H4: Saraçbendi HES | I4: 26.28 | J4: 40W000000004815F | K4: 920 | L4: PTF | M4: - | N4: 1613.17 | O4: 1535.83 | P4: 5095.11 | Q4: 11098.17 | R4: 9297.52 | S4: 2707.54 | T4: 631.89 | U4: 0 | V4: 123.43 | W4: 433.77 | X4: 1552.56 | Y4: 2582.36 | Z4: 3026.74 | AA4: 11880.73 | AB4: 12929.92 | AC4: 10562.16 | AD4: 6762.42 | AE4: 9734.47
A5: Otluca HES | B5: 48.77 | C5: 40W0000000045694 | D5: 1186 | E5: PTF | F5: - | H5: Otluca HES | I5: 48.77 | J5: 40W0000000045694 | K5: 1186 | L5: PTF | M5: - | N5: 14670.3 | O5: 5749.7 | P5: 11029.16 | Q5: 14418.99 | R5: 5635.4 | S5: 2606.57 | T5: 2255.2 | U5: 1579.7 | V5: 892.8 | W5: 1036.5 | X5: 1641.8 | Y5: 8699.8 | Z5: 19123.05 | AA5: 26463.28 | AB5: 22069.09 | AC5: 15586.67 | AD5: 7256.94 | AE5: 15212.08
A6: Demirciler HES | B6: 8.7 | C6: 40W000000005670A | D6: 1465 | E6: PTF | F6: - | H6: Demirciler HES | I6: 8.7 | J6: 40W000000005670A | K6: 1465 | L6: PTF | M6: - | N6: 3735.32 | O6: 1301.76 | P6: 709.99 | Q6: 2947.06 | R6: 1366.86 | S6: 383.35 | T6: 100.78 | U6: 52.57 | V6: 74 | W6: 469.02 | X6: 447.83 | Y6: 1527.29 | Z6: 3488.33 | AA6: 5186.02 | AB6: 2724.87 | AC6: 2522.04 | AD6: 823.12 | AE6: 832.75
A7: Yağmur HES | B7: 9.19 | C7: 40W000000005830E | D7: 1364 | E7: PTF | F7: - | H7: Yağmur HES | I7: 9.19 | J7: 40W000000005830E | K7: 1364 | L7: PTF | M7: - | N7: 1047.4 | O7: 809.78 | P7: 4544.73 | Q7: 5297.17 | R7: 2807.56 | S7: 843.86 | T7: 575.6 | U7: 497.93 | V7: 1852.79 | W7: 1679.51 | X7: 571.74 | Y7: 1153.38 | Z7: 2050.39 | AA7: 2365.26 | AB7: 2841.38 | AC7: 2800 | AD7: 1653.61 | AE7: 1673.23
A8: Kavakçalı HES | B8: 11.45 | C8: 40W000000006299Y | D8: 1461 | E8: PTF | F8: - | H8: Kavakçalı HES | I8: 11.45 | J8: 40W000000006299Y | K8: 1461 | L8: PTF | M8: - | N8: 6379.1 | O8: 2185.46 | P8: 1441.23 | Q8: 3970.51 | R8: 2775.63 | S8: 945.68 | T8: 567.72 | U8: 600.67 | V8: 469.31 | W8: 1038.76 | X8: 747.24 | Y8: 2001.44 | Z8: 4280.02 | AA8: 6389.28 | AB8: 3875.18 | AC8: 3260.28 | AD8: 865.75 | AE8: 1041.27
